{
  "id": "CVE-2015-3206",
  "assigner": "secalert@redhat.com",
  "last_modified": "2018-12-20T18:11:58.597",
  "vulnerable_configuration": [
    "cpe:2.3:a:apple:pykerberos:-:*:*:*:*:*:*:*"
  ],
  "cwe": "en",
  "summary": "The checkPassword function in python-kerberos does not authenticate the KDC it attempts to communicate with, which allows remote attackers to cause a denial of service (bad response), or have other unspecified impact by performing a man-in-the-middle attack.",
  "references": [
    "http://www.openwall.com/lists/oss-security/2015/05/21/3",
    "http://www.securityfocus.com/bid/74760",
    "https://bugzilla.redhat.com/show_bug.cgi?id=1223802",
    "https://github.com/apple/ccs-pykerberos/issues/31",
    "https://pypi.python.org/pypi/kerberos"
  ]
}